<?xml version="1.0" encoding="utf-8"?>
<!-- This URDF was automatically created by SolidWorks to URDF Exporter! Originally created by Stephen Brawner (brawner@gmail.com) 
     Commit Version: 1.6.0-4-g7f85cfe  Build Version: 1.6.7995.38578
     For more information, please see http://wiki.ros.org/sw_urdf_exporter -->
<robot
  name="Robotic_Arm_URDF">
  <link
    name="base_link">
    <inertial>
      <origin
        xyz="8.7138E-17 -2.3039E-17 0.073876"
        rpy="0 0 0" />
      <mass
        value="17.147" />
      <inertia
        ixx="0.192"
        ixy="-4.9423E-10"
        ixz="4.7227E-17"
        iyy="0.192"
        iyz="2.8496E-18"
        izz="0.29544" />
    </inertial>
    <visual>
      <origin
        xyz="0 0 0"
        rpy="0 0 0" />
      <geometry>
        <mesh
          filename="package://Robotic_Arm_URDF/meshes/base_link.STL" />
      </geometry>
      <material
        name="">
        <color
          rgba="0.79216 0.81961 0.93333 1" />
      </material>
    </visual>
    <collision>
      <origin
        xyz="0 0 0"
        rpy="0 0 0" />
      <geometry>
        <mesh
          filename="package://Robotic_Arm_URDF/meshes/base_link.STL" />
      </geometry>
    </collision>
  </link>
  <link
    name="Link_1">
    <inertial>
      <origin
        xyz="-2.5714E-14 0.11047 -7.8988E-11"
        rpy="0 0 0" />
      <mass
        value="3.0905" />
      <inertia
        ixx="0.026302"
        ixy="-2.5306E-15"
        ixz="-1.4177E-12"
        iyy="0.019632"
        iyz="-7.4535E-12"
        izz="0.025388" />
    </inertial>
    <visual>
      <origin
        xyz="0 0 0"
        rpy="0 0 0" />
      <geometry>
        <mesh
          filename="package://Robotic_Arm_URDF/meshes/Link_1.STL" />
      </geometry>
      <material
        name="">
        <color
          rgba="1 1 1 1" />
      </material>
    </visual>
    <collision>
      <origin
        xyz="0 0 0"
        rpy="0 0 0" />
      <geometry>
        <mesh
          filename="package://Robotic_Arm_URDF/meshes/Link_1.STL" />
      </geometry>
    </collision>
  </link>
  <joint
    name="Joint_1"
    type="revolute">
    <origin
      xyz="0 0 0.2"
      rpy="1.5708 0 1.5708" />
    <parent
      link="base_link" />
    <child
      link="Link_1" />
    <axis
      xyz="0 1 0" />
    <limit
      lower="0"
      upper="3.142"
      effort="300"
      velocity="3" />
  </joint>
  <link
    name="Link_2">
    <inertial>
      <origin
        xyz="1.7495E-17 -0.16752 -3.6581E-17"
        rpy="0 0 0" />
      <mass
        value="5.5867" />
      <inertia
        ixx="0.12632"
        ixy="1.2063E-17"
        ixz="-6.7457E-19"
        iyy="0.011401"
        iyz="-2.4824E-17"
        izz="0.12911" />
    </inertial>
    <visual>
      <origin
        xyz="0 0 0"
        rpy="0 0 0" />
      <geometry>
        <mesh
          filename="package://Robotic_Arm_URDF/meshes/Link_2.STL" />
      </geometry>
      <material
        name="">
        <color
          rgba="0.79216 0.81961 0.93333 1" />
      </material>
    </visual>
    <collision>
      <origin
        xyz="0 0 0"
        rpy="0 0 0" />
      <geometry>
        <mesh
          filename="package://Robotic_Arm_URDF/meshes/Link_2.STL" />
      </geometry>
    </collision>
  </link>
  <joint
    name="Joint_2"
    type="revolute">
    <origin
      xyz="0 0.205 0"
      rpy="0 0 3.1416" />
    <parent
      link="Link_1" />
    <child
      link="Link_2" />
    <axis
      xyz="0 0 -1" />
    <limit
      lower="-1.57"
      upper="1.57"
      effort="200"
      velocity="3" />
  </joint>
  <link
    name="Link_3">
    <inertial>
      <origin
        xyz="-0.17893 -5.5511E-17 -2.572E-09"
        rpy="0 0 0" />
      <mass
        value="2.8262" />
      <inertia
        ixx="0.0074041"
        ixy="5.1257E-18"
        ixz="-2.5477E-10"
        iyy="0.028552"
        iyz="-3.4736E-10"
        izz="0.025128" />
    </inertial>
    <visual>
      <origin
        xyz="0 0 0"
        rpy="0 0 0" />
      <geometry>
        <mesh
          filename="package://Robotic_Arm_URDF/meshes/Link_3.STL" />
      </geometry>
      <material
        name="">
        <color
          rgba="0.79216 0.81961 0.93333 1" />
      </material>
    </visual>
    <collision>
      <origin
        xyz="0 0 0"
        rpy="0 0 0" />
      <geometry>
        <mesh
          filename="package://Robotic_Arm_URDF/meshes/Link_3.STL" />
      </geometry>
    </collision>
  </link>
  <joint
    name="Joint_3"
    type="revolute">
    <origin
      xyz="0 -0.4 0"
      rpy="0 0 3.1416" />
    <parent
      link="Link_2" />
    <child
      link="Link_3" />
    <axis
      xyz="0 0 -1" />
    <limit
      lower="0"
      upper="3.142"
      effort="200"
      velocity="3" />
  </joint>
  <link
    name="Link_4">
    <inertial>
      <origin
        xyz="-0.051672 0 1.701E-16"
        rpy="0 0 0" />
      <mass
        value="1.8097" />
      <inertia
        ixx="0.0023112"
        ixy="-3.9856E-18"
        ixz="-1.1552E-18"
        iyy="0.0096102"
        iyz="-9.2113E-19"
        izz="0.0093908" />
    </inertial>
    <visual>
      <origin
        xyz="0 0 0"
        rpy="0 0 0" />
      <geometry>
        <mesh
          filename="package://Robotic_Arm_URDF/meshes/Link_4.STL" />
      </geometry>
      <material
        name="">
        <color
          rgba="0.79216 0.81961 0.93333 1" />
      </material>
    </visual>
    <collision>
      <origin
        xyz="0 0 0"
        rpy="0 0 0" />
      <geometry>
        <mesh
          filename="package://Robotic_Arm_URDF/meshes/Link_4.STL" />
      </geometry>
    </collision>
  </link>
  <joint
    name="Joint_4"
    type="revolute">
    <origin
      xyz="-0.35 0 0"
      rpy="0 0 1.5708" />
    <parent
      link="Link_3" />
    <child
      link="Link_4" />
    <axis
      xyz="0 0 1" />
    <limit
      lower="0"
      upper="-3.142"
      effort="200"
      velocity="3" />
  </joint>
  <link
    name="Link_5">
    <inertial>
      <origin
        xyz="-0.018544 0 1.5428E-16"
        rpy="0 0 0" />
      <mass
        value="0.19053" />
      <inertia
        ixx="0.00030197"
        ixy="3.1871E-20"
        ixz="-7.894E-21"
        iyy="0.00022817"
        iyz="-1.9664E-11"
        izz="0.00011843" />
    </inertial>
    <visual>
      <origin
        xyz="0 0 0"
        rpy="0 0 0" />
      <geometry>
        <mesh
          filename="package://Robotic_Arm_URDF/meshes/Link_5.STL" />
      </geometry>
      <material
        name="">
        <color
          rgba="0.79216 0.81961 0.93333 1" />
      </material>
    </visual>
    <collision>
      <origin
        xyz="0 0 0"
        rpy="0 0 0" />
      <geometry>
        <mesh
          filename="package://Robotic_Arm_URDF/meshes/Link_5.STL" />
      </geometry>
    </collision>
  </link>
  <joint
    name="Joint_5"
    type="revolute">
    <origin
      xyz="-0.188 0 0"
      rpy="0 0 0" />
    <parent
      link="Link_4" />
    <child
      link="Link_5" />
    <axis
      xyz="1 0 0" />
    <limit
      lower="0"
      upper="3.142"
      effort="200"
      velocity="3" />
  </joint>
  <link
    name="Link_6">
    <inertial>
      <origin
        xyz="-0.60237 0.4 -0.016013"
        rpy="0 0 0" />
      <mass
        value="0.11653" />
      <inertia
        ixx="3.9246E-05"
        ixy="4.2439E-20"
        ixz="1.0258E-05"
        iyy="7.1189E-05"
        iyz="4.9247E-20"
        izz="8.4875E-05" />
    </inertial>
    <visual>
      <origin
        xyz="0 0 0"
        rpy="0 0 0" />
      <geometry>
        <mesh
          filename="package://Robotic_Arm_URDF/meshes/Link_6.STL" />
      </geometry>
      <material
        name="">
        <color
          rgba="0.79216 0.81961 0.93333 1" />
      </material>
    </visual>
    <collision>
      <origin
        xyz="0 0 0"
        rpy="0 0 0" />
      <geometry>
        <mesh
          filename="package://Robotic_Arm_URDF/meshes/Link_6.STL" />
      </geometry>
    </collision>
  </link>
  <joint
    name="Joint_6"
    type="prismatic">
    <origin
      xyz="0.54 0.4 0"
      rpy="3.1416 0 0" />
    <parent
      link="Link_5" />
    <child
      link="Link_6" />
    <axis
      xyz="0 0 1" />
    <limit
      lower="0"
      upper="0.03"
      effort="100"
      velocity="3" />
  </joint>
  <link
    name="Link_7">
    <inertial>
      <origin
        xyz="-0.60237 0.4 -0.016013"
        rpy="0 0 0" />
      <mass
        value="0.11653" />
      <inertia
        ixx="3.9246E-05"
        ixy="1.2527E-19"
        ixz="1.0258E-05"
        iyy="7.1189E-05"
        iyz="-5.8458E-20"
        izz="8.4875E-05" />
    </inertial>
    <visual>
      <origin
        xyz="0 0 0"
        rpy="0 0 0" />
      <geometry>
        <mesh
          filename="package://Robotic_Arm_URDF/meshes/Link_7.STL" />
      </geometry>
      <material
        name="">
        <color
          rgba="0.79216 0.81961 0.93333 1" />
      </material>
    </visual>
    <collision>
      <origin
        xyz="0 0 0"
        rpy="0 0 0" />
      <geometry>
        <mesh
          filename="package://Robotic_Arm_URDF/meshes/Link_7.STL" />
      </geometry>
    </collision>
  </link>
  <joint
    name="Joint_7"
    type="prismatic">
    <origin
      xyz="0.54 -0.4 0"
      rpy="0 0 0" />
    <parent
      link="Link_5" />
    <child
      link="Link_7" />
    <axis
      xyz="0 0 -1" />
    <limit
      lower="-0.03"
      upper="0"
      effort="100"
      velocity="3" />
  </joint>
</robot>